Workbook

Sheet Resumão
A2: Pontuação Média da IA | B2: Nota Final (%) | C2: Pontos Totais (max 71) | D2: IA consegue gerar Texto? | E2: o texo é legivel? | F2: Resolução | G2: Qualidade Visual | H2: Enquadramento | I2: Alinhamento Prompt | J2: Alucinações | K2: Tamanho Prompt
A3: Gemini Nano Banana Pro | B3: =MEDIAN(Tabela[[#Totals],[Nota Final (%)]]) -> 83.098592 | C3: =MEDIAN(Tabela[[#Totals],[Pontos Totais (max 71)]]) -> 59 | D3: TRUE | E3: =AVERAGE(Tabela[o texo é legivel?]) -> 1.6388889 | F3: =AVERAGE(Tabela[Resolução]) -> 3.9444444 | G3: =AVERAGE(Tabela[Qualidade Visual]) -> 4.9722222 | H3: =AVERAGE(Tabela[Enquadramento]) -> 5 | I3: =AVERAGE(Tabela[Alinhamento Prompt]) -> 4.4444444 | J3: =MEDIAN(Tabela[Alucinações]) -> 5 | K3: =AVERAGE(Tabela[Tamanho Prompt]) -> 5
A4: Flow Stuido Nano Banana Pro | B4: =MEDIAN(Tabela_1[Nota Final (%)]) -> 81.690141 | C4: =MEDIAN(Tabela_1[Pontos Totais (max 71)]) -> 58 | D4: TRUE | E4: =AVERAGE('Flow Studio Nano banana Pro'!$E$2:$E$37) -> 1.4722222 | F4: =AVERAGE('Flow Studio Nano banana Pro'!$F$2:$F$37) -> 3 | G4: =AVERAGE('Flow Studio Nano banana Pro'!$G$2:$G$37) -> 4.9444444 | H4: =AVERAGE('Flow Studio Nano banana Pro'!$H$2:$H$37) -> 5 | I4: =AVERAGE('Flow Studio Nano banana Pro'!$I$2:$I$37) -> 4.75 | J4: =MEDIAN('Flow Studio Nano banana Pro'!$J$2:$J$37) -> 5 | K4: =AVERAGE('Flow Studio Nano banana Pro'!$K$2:$K$37) -> 5
A5: KlingAi | B5: =MEDIAN(Tabela_2[[#Totals],[Nota Final (%)]]) -> 76.056338 | C5: =MEDIAN(Tabela_2[[#Totals],[Pontos Totais (max 71)]]) -> 54 | D5: TRUE | E5: =AVERAGE(KlingAI!$E$2:$E$37) -> 0.83333333 | F5: =AVERAGE(KlingAI!$F$2:$F$37) -> 4 | G5: =AVERAGE(KlingAI!$G$2:$G$37) -> 5 | H5: =AVERAGE(KlingAI!$H$2:$H$37) -> 5 | I5: =AVERAGE(KlingAI!$I$2:$I$37) -> 4.3611111 | J5: =MEDIAN(KlingAI!$J$2:$J$37) -> 4 | K5: =AVERAGE(KlingAI!$K$2:$K$37) -> 4
A6: NetaYume Lumina - ComfyUI | B6: =MEDIAN(Tabela_5[Nota Final (%)]) -> 65.492958 | C6: =MEDIAN(Tabela_5[Pontos Totais (max 71)]) -> 46.5 | D6: TRUE | E6: =AVERAGE(Tabela_5[o texo é legivel?]) -> 0.36111111 | F6: =AVERAGE(Tabela_5[Resolução]) -> 3 | G6: =AVERAGE(Tabela_5[Qualidade Visual]) -> 4.3333333 | H6: =AVERAGE(Tabela_5[Enquadramento]) -> 4.75 | I6: =AVERAGE(Tabela_5[Alinhamento Prompt]) -> 3.6388889 | J6: =MEDIAN(Tabela_5[Alucinações]) -> 3 | K6: =AVERAGE(Tabela_5[Tamanho Prompt]) -> 5
A7: Juggernaut XL | B7: =MEDIAN(Tabela_3[Nota Final (%)]) -> 54.225352 | C7: =MEDIAN(Tabela_3[Pontos Totais (max 71)]) -> 38.5 | D7: TRUE | E7: =AVERAGE(Tabela_3[o texo é legivel?]) -> 0.11111111 | F7: =AVERAGE(Tabela_3[Resolução]) -> 3 | G7: =AVERAGE(Tabela_3[Qualidade Visual]) -> 3.8888889 | H7: =AVERAGE(Tabela_3[Enquadramento]) -> 5 | I7: =AVERAGE(Tabela_3[Alinhamento Prompt]) -> 2.4444444 | J7: =MEDIAN(Tabela_3[Alucinações]) -> 2 | K7: =AVERAGE(Tabela_3[Tamanho Prompt]) -> 5
A8: _CHEYENNE_ | B8: =MEDIAN(Tabela_4[Nota Final (%)]) -> 47.887324 | C8: =MEDIAN(Tabela_4[Pontos Totais (max 71)]) -> 34 | D8: FALSE | E8: =AVERAGE(Tabela_4[o texo é legivel?]) -> 0 | F8: =AVERAGE(Tabela_4[Resolução]) -> 3 | G8: =AVERAGE(Tabela_4[Qualidade Visual]) -> 3.3611111 | H8: =AVERAGE(Tabela_4[Enquadramento]) -> 3.8055556 | I8: =AVERAGE(Tabela_4[Alinhamento Prompt]) -> 1.9166667 | J8: =MEDIAN(Tabela_4[Alucinações]) -> 2 | K8: =AVERAGE(Tabela_4[Tamanho Prompt]) -> 5

Sheet Flow Studio Nano banana Pro
A1: Nome do Teste | B1: Nota Final (%) | C1: Pontos Totais (max 71) | D1: Tem Texto? | E1: o texo é legivel? | F1: Resolução | G1: Qualidade Visual | H1: Enquadramento | I1: Alinhamento Prompt | J1: Alucinações | K1: Tamanho Prompt
A2: Teste 1 - Personagem Pinkbob de frente - 15/12/2025 | B2: =C2/B49 * 100 -> 97.183099 | C2: =IF(D2, 1, 0) + (E2 * E49) + (F2 * F49) + (G2 * G49) + (H2 * H49) + (I2 * I49) + (J2 * J49) + (K2 * K49) -> 69 | D2: TRUE | E2: 5 | F2: 3 | G2: 5 | H2: 5 | I2: 5 | J2: 5 | K2: 5
A3: Teste 2 - Personagem Pinkbob de lado - 15/12/2025 | B3: =C3/B49 * 100 -> 97.183099 | C3: =IF(D3, 1, 0) + (E3 * E50) + (F3 * F50) + (G3 * G50) + (H3 * H50) + (I3 * I50) + (J3 * J50) + (K3 * K50) -> 69 | D3: TRUE | E3: 5 | F3: 3 | G3: 5 | H3: 5 | I3: 5 | J3: 5 | K3: 5
A4: Teste 3 - Personagem Pinkbob de costas - 15/12/2025 | B4: =C4/B49 * 100 -> 97.183099 | C4: =IF(D4, 1, 0) + (E4 * E51) + (F4 * F51) + (G4 * G51) + (H4 * H51) + (I4 * I51) + (J4 * J51) + (K4 * K51) -> 69 | D4: TRUE | E4: 5 | F4: 3 | G4: 5 | H4: 5 | I4: 5 | J4: 5 | K4: 5
A5: Teste 1 - Personagem2 Barba Rosa de frente - 15/12/2025 | B5: =C5/B49 * 100 -> 77.464789 | C5: =IF(D5, 1, 0) + (E5 * E52) + (F5 * F52) + (G5 * G52) + (H5 * H52) + (I5 * I52) + (J5 * J52) + (K5 * K52) -> 55 | D5: FALSE | E5: 0 | F5: 3 | G5: 5 | H5: 5 | I5: 4 | J5: 5 | K5: 5
A6: Teste 2 - Personagem2 Barba Rosa de lado - 15/12/2025 | B6: =C6/B49 * 100 -> 77.464789 | C6: =IF(D6, 1, 0) + (E6 * E53) + (F6 * F53) + (G6 * G53) + (H6 * H53) + (I6 * I53) + (J6 * J53) + (K6 * K53) -> 55 | D6: FALSE | E6: 0 | F6: 3 | G6: 5 | H6: 5 | I6: 4 | J6: 5 | K6: 5
A7: Teste 3 - Personagem2 Barba Rosa de costas - 15/12/2025 | B7: =C7/B49 * 100 -> 81.690141 | C7: =IF(D7, 1, 0) + (E7 * E54) + (F7 * F54) + (G7 * G54) + (H7 * H54) + (I7 * I54) + (J7 * J54) + (K7 * K54) -> 58 | D7: FALSE | E7: 0 | F7: 3 | G7: 5 | H7: 5 | I7: 5 | J7: 5 | K7: 5
A8: Teste 1 - Personagem3 João de frente - 16/12/2025 | B8: =C8/B49 * 100 -> 81.690141 | C8: =IF(D8, 1, 0) + (E8 * E55) + (F8 * F55) + (G8 * G55) + (H8 * H55) + (I8 * I55) + (J8 * J55) + (K8 * K55) -> 58 | D8: FALSE | E8: 0 | F8: 3 | G8: 5 | H8: 5 | I8: 5 | J8: 5 | K8: 5
A9: Teste 2 - Personagem3 João de lado - 16/12/2025 | B9: =C9/B49 * 100 -> 78.873239 | C9: =IF(D9, 1, 0) + (E9 * E56) + (F9 * F56) + (G9 * G56) + (H9 * H56) + (I9 * I56) + (J9 * J56) + (K9 * K56) -> 56 | D9: FALSE | E9: 0 | F9: 3 | G9: 4 | H9: 5 | I9: 5 | J9: 5 | K9: 5
A10: Teste 3 - Personagem3 João de costas - 16/12/2025 | B10: =C10/B49 * 100 -> 77.464789 | C10: =IF(D10, 1, 0) + (E10 * E57) + (F10 * F57) + (G10 * G57) + (H10 * H57) + (I10 * I57) + (J10 * J57) + (K10 * K57) -> 55 | D10: FALSE | E10: 0 | F10: 3 | G10: 5 | H10: 5 | I10: 4 | J10: 5 | K10: 5
A11: Teste 1 - Objeto bussola de frente - 18/12/2025 | B11: =C11/B49 * 100 -> 97.183099 | C11: =IF(D11, 1, 0) + (E11 * E58) + (F11 * F58) + (G11 * G58) + (H11 * H58) + (I11 * I58) + (J11 * J58) + (K11 * K58) -> 69 | D11: TRUE | E11: 5 | F11: 3 | G11: 5 | H11: 5 | I11: 5 | J11: 5 | K11: 5
A12: Teste 2 - Objeto bussola de lado - 18/12/2025 | B12: =C12/B49 * 100 -> 81.690141 | C12: =IF(D12, 1, 0) + (E12 * E59) + (F12 * F59) + (G12 * G59) + (H12 * H59) + (I12 * I59) + (J12 * J59) + (K12 * K59) -> 58 | D12: FALSE | E12: 0 | F12: 3 | G12: 5 | H12: 5 | I12: 5 | J12: 5 | K12: 5
A13: Teste 3 - Objeto bussola de costas - 18/12/2025 | B13: =C13/B49 * 100 -> 81.690141 | C13: =IF(D13, 1, 0) + (E13 * E60) + (F13 * F60) + (G13 * G60) + (H13 * H60) + (I13 * I60) + (J13 * J60) + (K13 * K60) -> 58 | D13: FALSE | E13: 0 | F13: 3 | G13: 5 | H13: 5 | I13: 5 | J13: 5 | K13: 5
A14: Teste 1 - Objeto2 mesa de frente - 18/12/2025 | B14: =C14/B49 * 100 -> 81.690141 | C14: =IF(D14, 1, 0) + (E14 * E61) + (F14 * F61) + (G14 * G61) + (H14 * H61) + (I14 * I61) + (J14 * J61) + (K14 * K61) -> 58 | D14: FALSE | E14: 0 | F14: 3 | G14: 5 | H14: 5 | I14: 5 | J14: 5 | K14: 5
A15: Teste 2 - Objeto2 mesa de lado - 18/12/2025 | B15: =C15/B49 * 100 -> 77.464789 | C15: =IF(D15, 1, 0) + (E15 * E62) + (F15 * F62) + (G15 * G62) + (H15 * H62) + (I15 * I62) + (J15 * J62) + (K15 * K62) -> 55 | D15: FALSE | E15: 0 | F15: 3 | G15: 5 | H15: 5 | I15: 4 | J15: 5 | K15: 5
A16: Teste 3 - Objeto2 mesa de costas - 18/12/2025 | B16: =C16/B49 * 100 -> 77.464789 | C16: =IF(D16, 1, 0) + (E16 * E63) + (F16 * F63) + (G16 * G63) + (H16 * H63) + (I16 * I63) + (J16 * J63) + (K16 * K63) -> 55 | D16: FALSE | E16: 0 | F16: 3 | G16: 5 | H16: 5 | I16: 4 | J16: 5 | K16: 5
A17: Teste 1 - Objeto3 espada pirata de frente - 23/12/2025 | B17: =C17/B49 * 100 -> 77.464789 | C17: =IF(D17, 1, 0) + (E17 * E64) + (F17 * F64) + (G17 * G64) + (H17 * H64) + (I17 * I64) + (J17 * J64) + (K17 * K64) -> 55 | D17: FALSE | E17: 0 | F17: 3 | G17: 5 | H17: 5 | I17: 4 | J17: 5 | K17: 5
A18: Teste 2 - Objeto3 espada pirata de lado - 23/12/2025 | B18: =C18/B49 * 100 -> 77.464789 | C18: =IF(D18, 1, 0) + (E18 * E65) + (F18 * F65) + (G18 * G65) + (H18 * H65) + (I18 * I65) + (J18 * J65) + (K18 * K65) -> 55 | D18: FALSE | E18: 0 | F18: 3 | G18: 5 | H18: 5 | I18: 4 | J18: 5 | K18: 5
A19: Teste 3 - Objeto3 espada pirata de costas - 23/12/2025 | B19: =C19/B49 * 100 -> 81.690141 | C19: =IF(D19, 1, 0) + (E19 * E66) + (F19 * F66) + (G19 * G66) + (H19 * H66) + (I19 * I66) + (J19 * J66) + (K19 * K66) -> 58 | D19: FALSE | E19: 0 | F19: 3 | G19: 5 | H19: 5 | I19: 5 | J19: 5 | K19: 5
A20: Teste 1 - Cenário Cabine Barba Rosa 2D - 25/12/2025 | B20: =C20/B49 * 100 -> 81.690141 | C20: =IF(D20, 1, 0) + (E20 * E67) + (F20 * F67) + (G20 * G67) + (H20 * H67) + (I20 * I67) + (J20 * J67) + (K20 * K67) -> 58 | D20: FALSE | E20: 0 | F20: 3 | G20: 5 | H20: 5 | I20: 5 | J20: 5 | K20: 5
A21: Teste 2 - Cenário Cabine Barba Rosa 2D Isométrico - 25/12/2025 | B21: =C21/B49 * 100 -> 77.464789 | C21: =IF(D21, 1, 0) + (E21 * E68) + (F21 * F68) + (G21 * G68) + (H21 * H68) + (I21 * I68) + (J21 * J68) + (K21 * K68) -> 55 | D21: FALSE | E21: 0 | F21: 3 | G21: 5 | H21: 5 | I21: 4 | J21: 5 | K21: 5
A22: Teste 3 - Cenário Cabine Barba Rosa 2D de cima - 25/12/2025 | B22: =C22/B49 * 100 -> 81.690141 | C22: =IF(D22, 1, 0) + (E22 * E69) + (F22 * F69) + (G22 * G69) + (H22 * H69) + (I22 * I69) + (J22 * J69) + (K22 * K69) -> 58 | D22: FALSE | E22: 0 | F22: 3 | G22: 5 | H22: 5 | I22: 5 | J22: 5 | K22: 5
A23: Teste 1 - Cenário2 Bar Pirata 2D - 26/12/2025 | B23: =C23/B49 * 100 -> 81.690141 | C23: =IF(D23, 1, 0) + (E23 * E70) + (F23 * F70) + (G23 * G70) + (H23 * H70) + (I23 * I70) + (J23 * J70) + (K23 * K70) -> 58 | D23: FALSE | E23: 0 | F23: 3 | G23: 5 | H23: 5 | I23: 5 | J23: 5 | K23: 5
A24: Teste 2 - Cenário2 Bar Pirata 2D Isométrico - 26/12/2025 | B24: =C24/B49 * 100 -> 81.690141 | C24: =IF(D24, 1, 0) + (E24 * E71) + (F24 * F71) + (G24 * G71) + (H24 * H71) + (I24 * I71) + (J24 * J71) + (K24 * K71) -> 58 | D24: FALSE | E24: 0 | F24: 3 | G24: 5 | H24: 5 | I24: 5 | J24: 5 | K24: 5
A25: Teste 3 - Cenário2 Bar Pirata 2D de cima - 26/12/2025 | B25: =C25/B49 * 100 -> 81.690141 | C25: =IF(D25, 1, 0) + (E25 * E72) + (F25 * F72) + (G25 * G72) + (H25 * H72) + (I25 * I72) + (J25 * J72) + (K25 * K72) -> 58 | D25: FALSE | E25: 0 | F25: 3 | G25: 5 | H25: 5 | I25: 5 | J25: 5 | K25: 5
A26: Teste 1 - Cenário3 Centro da cidade 2D - 26/12/2025 | B26: =C26/B49 * 100 -> 97.183099 | C26: =IF(D26, 1, 0) + (E26 * E73) + (F26 * F73) + (G26 * G73) + (H26 * H73) + (I26 * I73) + (J26 * J73) + (K26 * K73) -> 69 | D26: TRUE | E26: 5 | F26: 3 | G26: 5 | H26: 5 | I26: 5 | J26: 5 | K26: 5
A27: Teste 2 - Cenário3 Centro da cidade Isométrico - 26/12/2025 | B27: =C27/B49 * 100 -> 97.183099 | C27: =IF(D27, 1, 0) + (E27 * E74) + (F27 * F74) + (G27 * G74) + (H27 * H74) + (I27 * I74) + (J27 * J74) + (K27 * K74) -> 69 | D27: TRUE | E27: 5 | F27: 3 | G27: 5 | H27: 5 | I27: 5 | J27: 5 | K27: 5
A28: Teste 3 - Cenário3 Centro da cidade 2D de cima - 26/12/2025 | B28: =C28/B49 * 100 -> 90.140845 | C28: =IF(D28, 1, 0) + (E28 * E75) + (F28 * F75) + (G28 * G75) + (H28 * H75) + (I28 * I75) + (J28 * J75) + (K28 * K75) -> 64 | D28: TRUE | E28: 4 | F28: 3 | G28: 5 | H28: 5 | I28: 4 | J28: 5 | K28: 5
A29: Teste 1 - Textura de madeira - 26/12/2025 | B29: =C29/B49 * 100 -> 81.690141 | C29: =IF(D29, 1, 0) + (E29 * E76) + (F29 * F76) + (G29 * G76) + (H29 * H76) + (I29 * I76) + (J29 * J76) + (K29 * K76) -> 58 | D29: FALSE | E29: 0 | F29: 3 | G29: 5 | H29: 5 | I29: 5 | J29: 5 | K29: 5
A30: Teste 2 - Textura de mar/oceano - 26/12/2025 | B30: =C30/B49 * 100 -> 81.690141 | C30: =IF(D30, 1, 0) + (E30 * E77) + (F30 * F77) + (G30 * G77) + (H30 * H77) + (I30 * I77) + (J30 * J77) + (K30 * K77) -> 58 | D30: FALSE | E30: 0 | F30: 3 | G30: 5 | H30: 5 | I30: 5 | J30: 5 | K30: 5
A31: Teste 2 - Textura de parede com padrao que repete - 26/12/2025 | B31: =C31/B49 * 100 -> 81.690141 | C31: =IF(D31, 1, 0) + (E31 * E78) + (F31 * F78) + (G31 * G78) + (H31 * H78) + (I31 * I78) + (J31 * J78) + (K31 * K78) -> 58 | D31: FALSE | E31: 0 | F31: 3 | G31: 5 | H31: 5 | I31: 5 | J31: 5 | K31: 5
A32: Teste 1 - Arte da capa - 28/12/2025 | B32: =C32/B49 * 100 -> 85.915493 | C32: =IF(D32, 1, 0) + (E32 * E79) + (F32 * F79) + (G32 * G79) + (H32 * H79) + (I32 * I79) + (J32 * J79) + (K32 * K79) -> 61 | D32: TRUE | E32: 5 | F32: 3 | G32: 4 | H32: 5 | I32: 5 | J32: 3 | K32: 5
A33: Teste 2 - Arte da tela de configurações - 28/12/2025 | B33: =C33/B49 * 100 -> 92.957746 | C33: =IF(D33, 1, 0) + (E33 * E80) + (F33 * F80) + (G33 * G80) + (H33 * H80) + (I33 * I80) + (J33 * J80) + (K33 * K80) -> 66 | D33: TRUE | E33: 5 | F33: 3 | G33: 5 | H33: 5 | I33: 5 | J33: 4 | K33: 5
A34: Teste 3 - Arte da tela de ajuda - 28/12/2025 | B34: =C34/B49 * 100 -> 94.366197 | C34: =IF(D34, 1, 0) + (E34 * E81) + (F34 * F81) + (G34 * G81) + (H34 * H81) + (I34 * I81) + (J34 * J81) + (K34 * K81) -> 67 | D34: TRUE | E34: 4 | F34: 3 | G34: 5 | H34: 5 | I34: 5 | J34: 5 | K34: 5
A35: Teste 1 - Botão - 29/12/2025 | B35: =C35/B49 * 100 -> 97.183099 | C35: =IF(D35, 1, 0) + (E35 * E82) + (F35 * F82) + (G35 * G82) + (H35 * H82) + (I35 * I82) + (J35 * J82) + (K35 * K82) -> 69 | D35: TRUE | E35: 5 | F35: 3 | G35: 5 | H35: 5 | I35: 5 | J35: 5 | K35: 5
A36: Teste 2 - Inventário - 29/12/2025 | B36: =C36/B49 * 100 -> 81.690141 | C36: =IF(D36, 1, 0) + (E36 * E83) + (F36 * F83) + (G36 * G83) + (H36 * H83) + (I36 * I83) + (J36 * J83) + (K36 * K83) -> 58 | D36: FALSE | E36: 0 | F36: 3 | G36: 5 | H36: 5 | I36: 5 | J36: 5 | K36: 5
A37: Teste 3 - Cursor - 29/12/2025 | B37: =C37/B49 * 100 -> 81.690141 | C37: =IF(D37, 1, 0) + (E37 * E84) + (F37 * F84) + (G37 * G84) + (H37 * H84) + (I37 * I84) + (J37 * J84) + (K37 * K84) -> 58 | D37: FALSE | E37: 0 | F37: 3 | G37: 5 | H37: 5 | I37: 5 | J37: 5 | K37: 5
A38: Médias | B38: =MEDIAN(Tabela_1[Nota Final (%)]) -> 81.690141 | C38: =MEDIAN(Tabela_1[Pontos Totais (max 71)]) -> 58 | E38: =AVERAGE(Tabela_1[o texo é legivel?]) -> 1.4722222 | F38: =AVERAGE(Tabela_1[Resolução]) -> 3 | G38: =AVERAGE(Tabela_1[Qualidade Visual]) -> 4.9444444 | H38: =AVERAGE(Tabela_1[Enquadramento]) -> 5 | I38: =AVERAGE(Tabela_1[Alinhamento Prompt]) -> 4.75 | J38: =MEDIAN(Tabela_1[Alucinações]) -> 5 | K38: =AVERAGE(Tabela_1[Tamanho Prompt]) -> 5
J40: 0 é que tem alucinação e 5 não tem
A49: Max de pontos | B49: =1 + (5 * E49) + (5 * F49) + (5 * G49) + (5 * H49) + (5 * I49) + (5* J49) + (5* K49) -> 71 | C49: Pesos | D49: 1 | E49: 2 | F49: 1 | G49: 2 | H49: 1 | I49: 3 | J49: 3 | K49: 2
...

Sheet Gemini Nano Banana Pro
A1: Nome do Teste | B1: Nota Final (%) | C1: Pontos Totais (max 71) | D1: Tem Texto? | E1: o texo é legivel? | F1: Resolução | G1: Qualidade Visual | H1: Enquadramento | I1: Alinhamento Prompt | J1: Alucinações | K1: Tamanho Prompt
A2: Teste 1 - Personagem Pinkbob de frente - 15/12/2025 | B2: =C2/B49 * 100 -> 90.140845 | C2: =IF(D2, 1, 0) + (E2 * E49) + (F2 * F49) + (G2 * G49) + (H2 * H49) + (I2 * I49) + (J2 * J49) + (K2 * K49) -> 64 | D2: TRUE | E2: 5 | F2: 4 | G2: 5 | H2: 5 | I2: 4 | J2: 4 | K2: 5
A3: Teste 2 - Personagem Pinkbob de lado - 15/12/2025 | B3: =C3/B49 * 100 -> 90.140845 | C3: =IF(D3, 1, 0) + (E3 * E50) + (F3 * F50) + (G3 * G50) + (H3 * H50) + (I3 * I50) + (J3 * J50) + (K3 * K50) -> 64 | D3: TRUE | E3: 5 | F3: 4 | G3: 5 | H3: 5 | I3: 4 | J3: 4 | K3: 5
A4: Teste 3 - Personagem Pinkbob de costas - 15/12/2025 | B4: =C4/B49 * 100 -> 85.915493 | C4: =IF(D4, 1, 0) + (E4 * E51) + (F4 * F51) + (G4 * G51) + (H4 * H51) + (I4 * I51) + (J4 * J51) + (K4 * K51) -> 61 | D4: TRUE | E4: 5 | F4: 4 | G4: 5 | H4: 5 | I4: 4 | J4: 3 | K4: 5
A5: Teste 1 - Personagem2 Barba Rosa de frente - 15/12/2025 | B5: =C5/B49 * 100 -> 74.647887 | C5: =IF(D5, 1, 0) + (E5 * E52) + (F5 * F52) + (G5 * G52) + (H5 * H52) + (I5 * I52) + (J5 * J52) + (K5 * K52) -> 53 | D5: FALSE | E5: 0 | F5: 4 | G5: 5 | H5: 5 | I5: 4 | J5: 4 | K5: 5
A6: Teste 2 - Personagem2 Barba Rosa de lado - 15/12/2025 | B6: =C6/B49 * 100 -> 70.422535 | C6: =IF(D6, 1, 0) + (E6 * E53) + (F6 * F53) + (G6 * G53) + (H6 * H53) + (I6 * I53) + (J6 * J53) + (K6 * K53) -> 50 | D6: FALSE | E6: 0 | F6: 4 | G6: 5 | H6: 5 | I6: 4 | J6: 3 | K6: 5
A7: Teste 3 - Personagem2 Barba Rosa de costas - 15/12/2025 | B7: =C7/B49 * 100 -> 74.647887 | C7: =IF(D7, 1, 0) + (E7 * E54) + (F7 * F54) + (G7 * G54) + (H7 * H54) + (I7 * I54) + (J7 * J54) + (K7 * K54) -> 53 | D7: FALSE | E7: 0 | F7: 4 | G7: 5 | H7: 5 | I7: 4 | J7: 4 | K7: 5
A8: Teste 1 - Personagem3 João de frente - 16/12/2025 | B8: =C8/B49 * 100 -> 70.422535 | C8: =IF(D8, 1, 0) + (E8 * E55) + (F8 * F55) + (G8 * G55) + (H8 * H55) + (I8 * I55) + (J8 * J55) + (K8 * K55) -> 50 | D8: FALSE | E8: 0 | F8: 4 | G8: 5 | H8: 5 | I8: 4 | J8: 3 | K8: 5
A9: Teste 2 - Personagem3 João de lado - 16/12/2025 | B9: =C9/B49 * 100 -> 66.197183 | C9: =IF(D9, 1, 0) + (E9 * E56) + (F9 * F56) + (G9 * G56) + (H9 * H56) + (I9 * I56) + (J9 * J56) + (K9 * K56) -> 47 | D9: FALSE | E9: 0 | F9: 4 | G9: 5 | H9: 5 | I9: 3 | J9: 3 | K9: 5
A10: Teste 3 - Personagem3 João de costas - 16/12/2025 | B10: =C10/B49 * 100 -> 74.647887 | C10: =IF(D10, 1, 0) + (E10 * E57) + (F10 * F57) + (G10 * G57) + (H10 * H57) + (I10 * I57) + (J10 * J57) + (K10 * K57) -> 53 | D10: FALSE | E10: 0 | F10: 4 | G10: 5 | H10: 5 | I10: 4 | J10: 4 | K10: 5
A11: Teste 1 - Objeto bussola de frente - 18/12/2025 | B11: =C11/B49 * 100 -> 78.873239 | C11: =IF(D11, 1, 0) + (E11 * E58) + (F11 * F58) + (G11 * G58) + (H11 * H58) + (I11 * I58) + (J11 * J58) + (K11 * K58) -> 56 | D11: FALSE | E11: 0 | F11: 4 | G11: 5 | H11: 5 | I11: 5 | J11: 4 | K11: 5
A12: Teste 2 - Objeto bussola de lado - 18/12/2025 | B12: =C12/B49 * 100 -> 83.098592 | C12: =IF(D12, 1, 0) + (E12 * E59) + (F12 * F59) + (G12 * G59) + (H12 * H59) + (I12 * I59) + (J12 * J59) + (K12 * K59) -> 59 | D12: FALSE | E12: 0 | F12: 4 | G12: 5 | H12: 5 | I12: 5 | J12: 5 | K12: 5
A13: Teste 3 - Objeto bussola de costas - 18/12/2025 | B13: =C13/B49 * 100 -> 83.098592 | C13: =IF(D13, 1, 0) + (E13 * E60) + (F13 * F60) + (G13 * G60) + (H13 * H60) + (I13 * I60) + (J13 * J60) + (K13 * K60) -> 59 | D13: FALSE | E13: 0 | F13: 4 | G13: 5 | H13: 5 | I13: 5 | J13: 5 | K13: 5
A14: Teste 1 - Objeto2 mesa de frente - 18/12/2025 | B14: =C14/B49 * 100 -> 77.464789 | C14: =IF(D14, 1, 0) + (E14 * E61) + (F14 * F61) + (G14 * G61) + (H14 * H61) + (I14 * I61) + (J14 * J61) + (K14 * K61) -> 55 | D14: FALSE | E14: 0 | F14: 3 | G14: 5 | H14: 5 | I14: 4 | J14: 5 | K14: 5
A15: Teste 2 - Objeto2 mesa de lado - 18/12/2025 | B15: =C15/B49 * 100 -> 78.873239 | C15: =IF(D15, 1, 0) + (E15 * E62) + (F15 * F62) + (G15 * G62) + (H15 * H62) + (I15 * I62) + (J15 * J62) + (K15 * K62) -> 56 | D15: FALSE | E15: 0 | F15: 4 | G15: 5 | H15: 5 | I15: 4 | J15: 5 | K15: 5
A16: Teste 3 - Objeto2 mesa de costas - 18/12/2025 | B16: =C16/B49 * 100 -> 78.873239 | C16: =IF(D16, 1, 0) + (E16 * E63) + (F16 * F63) + (G16 * G63) + (H16 * H63) + (I16 * I63) + (J16 * J63) + (K16 * K63) -> 56 | D16: FALSE | E16: 0 | F16: 4 | G16: 5 | H16: 5 | I16: 4 | J16: 5 | K16: 5
A17: Teste 1 - Objeto3 espada pirata de frente - 23/12/2025 | B17: =C17/B49 * 100 -> 78.873239 | C17: =IF(D17, 1, 0) + (E17 * E64) + (F17 * F64) + (G17 * G64) + (H17 * H64) + (I17 * I64) + (J17 * J64) + (K17 * K64) -> 56 | D17: FALSE | E17: 0 | F17: 4 | G17: 5 | H17: 5 | I17: 4 | J17: 5 | K17: 5
A18: Teste 2 - Objeto3 espada pirata de lado - 23/12/2025 | B18: =C18/B49 * 100 -> 78.873239 | C18: =IF(D18, 1, 0) + (E18 * E65) + (F18 * F65) + (G18 * G65) + (H18 * H65) + (I18 * I65) + (J18 * J65) + (K18 * K65) -> 56 | D18: FALSE | E18: 0 | F18: 4 | G18: 5 | H18: 5 | I18: 4 | J18: 5 | K18: 5
A19: Teste 3 - Objeto3 espada pirata de costas - 23/12/2025 | B19: =C19/B49 * 100 -> 78.873239 | C19: =IF(D19, 1, 0) + (E19 * E66) + (F19 * F66) + (G19 * G66) + (H19 * H66) + (I19 * I66) + (J19 * J66) + (K19 * K66) -> 56 | D19: FALSE | E19: 0 | F19: 4 | G19: 5 | H19: 5 | I19: 4 | J19: 5 | K19: 5
A20: Teste 1 - Cenário Cabine Barba Rosa 2D - 25/12/2025 | B20: =C20/B49 * 100 -> 83.098592 | C20: =IF(D20, 1, 0) + (E20 * E67) + (F20 * F67) + (G20 * G67) + (H20 * H67) + (I20 * I67) + (J20 * J67) + (K20 * K67) -> 59 | D20: FALSE | E20: 0 | F20: 4 | G20: 5 | H20: 5 | I20: 5 | J20: 5 | K20: 5
A21: Teste 2 - Cenário Cabine Barba Rosa 2D Isométrico - 25/12/2025 | B21: =C21/B49 * 100 -> 83.098592 | C21: =IF(D21, 1, 0) + (E21 * E68) + (F21 * F68) + (G21 * G68) + (H21 * H68) + (I21 * I68) + (J21 * J68) + (K21 * K68) -> 59 | D21: FALSE | E21: 0 | F21: 4 | G21: 5 | H21: 5 | I21: 5 | J21: 5 | K21: 5
A22: Teste 3 - Cenário Cabine Barba Rosa 2D de cima - 25/12/2025 | B22: =C22/B49 * 100 -> 83.098592 | C22: =IF(D22, 1, 0) + (E22 * E69) + (F22 * F69) + (G22 * G69) + (H22 * H69) + (I22 * I69) + (J22 * J69) + (K22 * K69) -> 59 | D22: FALSE | E22: 0 | F22: 4 | G22: 5 | H22: 5 | I22: 5 | J22: 5 | K22: 5
A23: Teste 1 - Cenário2 Bar Pirata 2D - 26/12/2025 | B23: =C23/B49 * 100 -> 83.098592 | C23: =IF(D23, 1, 0) + (E23 * E70) + (F23 * F70) + (G23 * G70) + (H23 * H70) + (I23 * I70) + (J23 * J70) + (K23 * K70) -> 59 | D23: FALSE | E23: 0 | F23: 4 | G23: 5 | H23: 5 | I23: 5 | J23: 5 | K23: 5
A24: Teste 2 - Cenário2 Bar Pirata 2D Isométrico - 26/12/2025 | B24: =C24/B49 * 100 -> 83.098592 | C24: =IF(D24, 1, 0) + (E24 * E71) + (F24 * F71) + (G24 * G71) + (H24 * H71) + (I24 * I71) + (J24 * J71) + (K24 * K71) -> 59 | D24: FALSE | E24: 0 | F24: 4 | G24: 5 | H24: 5 | I24: 5 | J24: 5 | K24: 5
A25: Teste 3 - Cenário2 Bar Pirata 2D de cima - 26/12/2025 | B25: =C25/B49 * 100 -> 78.873239 | C25: =IF(D25, 1, 0) + (E25 * E72) + (F25 * F72) + (G25 * G72) + (H25 * H72) + (I25 * I72) + (J25 * J72) + (K25 * K72) -> 56 | D25: FALSE | E25: 0 | F25: 4 | G25: 5 | H25: 5 | I25: 5 | J25: 4 | K25: 5
A26: Teste 1 - Cenário3 Centro da cidade 2D - 26/12/2025 | B26: =C26/B49 * 100 -> 98.591549 | C26: =IF(D26, 1, 0) + (E26 * E73) + (F26 * F73) + (G26 * G73) + (H26 * H73) + (I26 * I73) + (J26 * J73) + (K26 * K73) -> 70 | D26: TRUE | E26: 5 | F26: 4 | G26: 5 | H26: 5 | I26: 5 | J26: 5 | K26: 5
A27: Teste 2 - Cenário3 Centro da cidade Isométrico - 26/12/2025 | B27: =C27/B49 * 100 -> 98.591549 | C27: =IF(D27, 1, 0) + (E27 * E74) + (F27 * F74) + (G27 * G74) + (H27 * H74) + (I27 * I74) + (J27 * J74) + (K27 * K74) -> 70 | D27: TRUE | E27: 5 | F27: 4 | G27: 5 | H27: 5 | I27: 5 | J27: 5 | K27: 5
A28: Teste 3 - Cenário3 Centro da cidade 2D de cima - 26/12/2025 | B28: =C28/B49 * 100 -> 91.549296 | C28: =IF(D28, 1, 0) + (E28 * E75) + (F28 * F75) + (G28 * G75) + (H28 * H75) + (I28 * I75) + (J28 * J75) + (K28 * K75) -> 65 | D28: TRUE | E28: 4 | F28: 4 | G28: 5 | H28: 5 | I28: 4 | J28: 5 | K28: 5
A29: Teste 1 - Textura de madeira - 26/12/2025 | B29: =C29/B49 * 100 -> 78.873239 | C29: =IF(D29, 1, 0) + (E29 * E76) + (F29 * F76) + (G29 * G76) + (H29 * H76) + (I29 * I76) + (J29 * J76) + (K29 * K76) -> 56 | D29: FALSE | E29: 0 | F29: 4 | G29: 5 | H29: 5 | I29: 4 | J29: 5 | K29: 5
A30: Teste 2 - Textura de mar/oceano - 26/12/2025 | B30: =C30/B49 * 100 -> 83.098592 | C30: =IF(D30, 1, 0) + (E30 * E77) + (F30 * F77) + (G30 * G77) + (H30 * H77) + (I30 * I77) + (J30 * J77) + (K30 * K77) -> 59 | D30: FALSE | E30: 0 | F30: 4 | G30: 5 | H30: 5 | I30: 5 | J30: 5 | K30: 5
A31: Teste 2 - Textura de parede com padrao que repete - 26/12/2025 | B31: =C31/B49 * 100 -> 78.873239 | C31: =IF(D31, 1, 0) + (E31 * E78) + (F31 * F78) + (G31 * G78) + (H31 * H78) + (I31 * I78) + (J31 * J78) + (K31 * K78) -> 56 | D31: FALSE | E31: 0 | F31: 4 | G31: 5 | H31: 5 | I31: 4 | J31: 5 | K31: 5
A32: Teste 1 - Arte da capa - 28/12/2025 | B32: =C32/B49 * 100 -> 94.366197 | C32: =IF(D32, 1, 0) + (E32 * E79) + (F32 * F79) + (G32 * G79) + (H32 * H79) + (I32 * I79) + (J32 * J79) + (K32 * K79) -> 67 | D32: TRUE | E32: 5 | F32: 3 | G32: 4 | H32: 5 | I32: 5 | J32: 5 | K32: 5
A33: Teste 2 - Arte da tela de configurações - 28/12/2025 | B33: =C33/B49 * 100 -> 98.591549 | C33: =IF(D33, 1, 0) + (E33 * E80) + (F33 * F80) + (G33 * G80) + (H33 * H80) + (I33 * I80) + (J33 * J80) + (K33 * K80) -> 70 | D33: TRUE | E33: 5 | F33: 4 | G33: 5 | H33: 5 | I33: 5 | J33: 5 | K33: 5
A34: Teste 3 - Arte da tela de ajuda - 28/12/2025 | B34: =C34/B49 * 100 -> 98.591549 | C34: =IF(D34, 1, 0) + (E34 * E81) + (F34 * F81) + (G34 * G81) + (H34 * H81) + (I34 * I81) + (J34 * J81) + (K34 * K81) -> 70 | D34: TRUE | E34: 5 | F34: 4 | G34: 5 | H34: 5 | I34: 5 | J34: 5 | K34: 5
A35: Teste 1 - Botão - 29/12/2025 | B35: =C35/B49 * 100 -> 98.591549 | C35: =IF(D35, 1, 0) + (E35 * E82) + (F35 * F82) + (G35 * G82) + (H35 * H82) + (I35 * I82) + (J35 * J82) + (K35 * K82) -> 70 | D35: TRUE | E35: 5 | F35: 4 | G35: 5 | H35: 5 | I35: 5 | J35: 5 | K35: 5
A36: Teste 2 - Inventário - 29/12/2025 | B36: =C36/B49 * 100 -> 92.957746 | C36: =IF(D36, 1, 0) + (E36 * E83) + (F36 * F83) + (G36 * G83) + (H36 * H83) + (I36 * I83) + (J36 * J83) + (K36 * K83) -> 66 | D36: FALSE | E36: 5 | F36: 4 | G36: 5 | H36: 5 | I36: 4 | J36: 5 | K36: 5
A37: Teste 3 - Cursor - 29/12/2025 | B37: =C37/B49 * 100 -> 97.183099 | C37: =IF(D37, 1, 0) + (E37 * E84) + (F37 * F84) + (G37 * G84) + (H37 * H84) + (I37 * I84) + (J37 * J84) + (K37 * K84) -> 69 | D37: FALSE | E37: 5 | F37: 4 | G37: 5 | H37: 5 | I37: 5 | J37: 5 | K37: 5
A38: Médias | B38: =MEDIAN(Tabela[Nota Final (%)]) -> 83.098592 | C38: =MEDIAN(Tabela[Pontos Totais (max 71)]) -> 59 | E38: =AVERAGE(Tabela[o texo é legivel?]) -> 1.6388889 | F38: =AVERAGE(Tabela[Resolução]) -> 3.9444444 | G38: =AVERAGE(Tabela[Qualidade Visual]) -> 4.9722222 | H38: =AVERAGE(Tabela[Enquadramento]) -> 5 | I38: =AVERAGE(Tabela[Alinhamento Prompt]) -> 4.4444444 | J38: =MEDIAN(Tabela[Alucinações]) -> 5 | K38: =AVERAGE(Tabela[Tamanho Prompt]) -> 5
J40: 0 é que tem muita alucinação e 5 não tem
A49: Max de pontos | B49: =1 + (5 * E49) + (5 * F49) + (5 * G49) + (5 * H49) + (5 * I49) + (5* J49) + (5* K49) -> 71 | C49: Pesos | D49: 1 | E49: 2 | F49: 1 | G49: 2 | H49: 1 | I49: 3 | J49: 3 | K49: 2
...

Sheet KlingAI
A1: Nome do Teste | B1: Nota Final (%) | C1: Pontos Totais (max 71) | D1: Tem Texto? | E1: o texo é legivel? | F1: Resolução | G1: Qualidade Visual | H1: Enquadramento | I1: Alinhamento Prompt | J1: Alucinações | K1: Tamanho Prompt
A2: Teste 1 - Personagem Pinkbob de frente - 15/12/2025 | B2: =C2/B49 * 100 -> 95.774648 | C2: =IF(D2, 1, 0) + (E2 * E49) + (F2 * F49) + (G2 * G49) + (H2 * H49) + (I2 * I49) + (J2 * J49) + (K2 * K49) -> 68 | D2: TRUE | E2: 5 | F2: 4 | G2: 5 | H2: 5 | I2: 5 | J2: 5 | K2: 4
A3: Teste 2 - Personagem Pinkbob de lado - 15/12/2025 | B3: =C3/B49 * 100 -> 91.549296 | C3: =IF(D3, 1, 0) + (E3 * E50) + (F3 * F50) + (G3 * G50) + (H3 * H50) + (I3 * I50) + (J3 * J50) + (K3 * K50) -> 65 | D3: TRUE | E3: 5 | F3: 4 | G3: 5 | H3: 5 | I3: 5 | J3: 4 | K3: 4
A4: Teste 3 - Personagem Pinkbob de costas - 15/12/2025 | B4: =C4/B49 * 100 -> 91.549296 | C4: =IF(D4, 1, 0) + (E4 * E51) + (F4 * F51) + (G4 * G51) + (H4 * H51) + (I4 * I51) + (J4 * J51) + (K4 * K51) -> 65 | D4: TRUE | E4: 5 | F4: 4 | G4: 5 | H4: 5 | I4: 5 | J4: 4 | K4: 4
A5: Teste 1 - Personagem2 Barba Rosa de frente - 15/12/2025 | B5: =C5/B49 * 100 -> 80.28169 | C5: =IF(D5, 1, 0) + (E5 * E52) + (F5 * F52) + (G5 * G52) + (H5 * H52) + (I5 * I52) + (J5 * J52) + (K5 * K52) -> 57 | D5: FALSE | E5: 0 | F5: 4 | G5: 5 | H5: 5 | I5: 5 | J5: 5 | K5: 4
A6: Teste 2 - Personagem2 Barba Rosa de lado - 15/12/2025 | B6: =C6/B49 * 100 -> 76.056338 | C6: =IF(D6, 1, 0) + (E6 * E53) + (F6 * F53) + (G6 * G53) + (H6 * H53) + (I6 * I53) + (J6 * J53) + (K6 * K53) -> 54 | D6: FALSE | E6: 0 | F6: 4 | G6: 5 | H6: 5 | I6: 4 | J6: 5 | K6: 4
A7: Teste 3 - Personagem2 Barba Rosa de costas - 15/12/2025 | B7: =C7/B49 * 100 -> 76.056338 | C7: =IF(D7, 1, 0) + (E7 * E54) + (F7 * F54) + (G7 * G54) + (H7 * H54) + (I7 * I54) + (J7 * J54) + (K7 * K54) -> 54 | D7: FALSE | E7: 0 | F7: 4 | G7: 5 | H7: 5 | I7: 4 | J7: 5 | K7: 4
A8: Teste 1 - Personagem3 João de frente - 16/12/2025 | B8: =C8/B49 * 100 -> 76.056338 | C8: =IF(D8, 1, 0) + (E8 * E55) + (F8 * F55) + (G8 * G55) + (H8 * H55) + (I8 * I55) + (J8 * J55) + (K8 * K55) -> 54 | D8: FALSE | E8: 0 | F8: 4 | G8: 5 | H8: 5 | I8: 5 | J8: 4 | K8: 4
A9: Teste 2 - Personagem3 João de lado - 16/12/2025 | B9: =C9/B49 * 100 -> 76.056338 | C9: =IF(D9, 1, 0) + (E9 * E56) + (F9 * F56) + (G9 * G56) + (H9 * H56) + (I9 * I56) + (J9 * J56) + (K9 * K56) -> 54 | D9: FALSE | E9: 0 | F9: 4 | G9: 5 | H9: 5 | I9: 5 | J9: 4 | K9: 4
A10: Teste 3 - Personagem3 João de costas - 16/12/2025 | B10: =C10/B49 * 100 -> 71.830986 | C10: =IF(D10, 1, 0) + (E10 * E57) + (F10 * F57) + (G10 * G57) + (H10 * H57) + (I10 * I57) + (J10 * J57) + (K10 * K57) -> 51 | D10: FALSE | E10: 0 | F10: 4 | G10: 5 | H10: 5 | I10: 5 | J10: 3 | K10: 4
A11: Teste 1 - Objeto bussola de frente - 18/12/2025 | B11: =C11/B49 * 100 -> 80.28169 | C11: =IF(D11, 1, 0) + (E11 * E58) + (F11 * F58) + (G11 * G58) + (H11 * H58) + (I11 * I58) + (J11 * J58) + (K11 * K58) -> 57 | D11: FALSE | E11: 0 | F11: 4 | G11: 5 | H11: 5 | I11: 5 | J11: 5 | K11: 4
A12: Teste 2 - Objeto bussola de lado - 18/12/2025 | B12: =C12/B49 * 100 -> 76.056338 | C12: =IF(D12, 1, 0) + (E12 * E59) + (F12 * F59) + (G12 * G59) + (H12 * H59) + (I12 * I59) + (J12 * J59) + (K12 * K59) -> 54 | D12: FALSE | E12: 0 | F12: 4 | G12: 5 | H12: 5 | I12: 4 | J12: 5 | K12: 4
A13: Teste 3 - Objeto bussola de costas - 18/12/2025 | B13: =C13/B49 * 100 -> 80.28169 | C13: =IF(D13, 1, 0) + (E13 * E60) + (F13 * F60) + (G13 * G60) + (H13 * H60) + (I13 * I60) + (J13 * J60) + (K13 * K60) -> 57 | D13: FALSE | E13: 0 | F13: 4 | G13: 5 | H13: 5 | I13: 5 | J13: 5 | K13: 4
A14: Teste 1 - Objeto2 mesa de frente - 18/12/2025 | B14: =C14/B49 * 100 -> 76.056338 | C14: =IF(D14, 1, 0) + (E14 * E61) + (F14 * F61) + (G14 * G61) + (H14 * H61) + (I14 * I61) + (J14 * J61) + (K14 * K61) -> 54 | D14: FALSE | E14: 0 | F14: 4 | G14: 5 | H14: 5 | I14: 4 | J14: 5 | K14: 4
A15: Teste 2 - Objeto2 mesa de lado - 18/12/2025 | B15: =C15/B49 * 100 -> 76.056338 | C15: =IF(D15, 1, 0) + (E15 * E62) + (F15 * F62) + (G15 * G62) + (H15 * H62) + (I15 * I62) + (J15 * J62) + (K15 * K62) -> 54 | D15: FALSE | E15: 0 | F15: 4 | G15: 5 | H15: 5 | I15: 4 | J15: 5 | K15: 4
A16: Teste 3 - Objeto2 mesa de costas - 18/12/2025 | B16: =C16/B49 * 100 -> 76.056338 | C16: =IF(D16, 1, 0) + (E16 * E63) + (F16 * F63) + (G16 * G63) + (H16 * H63) + (I16 * I63) + (J16 * J63) + (K16 * K63) -> 54 | D16: FALSE | E16: 0 | F16: 4 | G16: 5 | H16: 5 | I16: 4 | J16: 5 | K16: 4
A17: Teste 1 - Objeto3 espada pirata de frente - 23/12/2025 | B17: =C17/B49 * 100 -> 71.830986 | C17: =IF(D17, 1, 0) + (E17 * E64) + (F17 * F64) + (G17 * G64) + (H17 * H64) + (I17 * I64) + (J17 * J64) + (K17 * K64) -> 51 | D17: FALSE | E17: 0 | F17: 4 | G17: 5 | H17: 5 | I17: 4 | J17: 4 | K17: 4
A18: Teste 2 - Objeto3 espada pirata de lado - 23/12/2025 | B18: =C18/B49 * 100 -> 71.830986 | C18: =IF(D18, 1, 0) + (E18 * E65) + (F18 * F65) + (G18 * G65) + (H18 * H65) + (I18 * I65) + (J18 * J65) + (K18 * K65) -> 51 | D18: FALSE | E18: 0 | F18: 4 | G18: 5 | H18: 5 | I18: 4 | J18: 4 | K18: 4
A19: Teste 3 - Objeto3 espada pirata de costas - 23/12/2025 | B19: =C19/B49 * 100 -> 71.830986 | C19: =IF(D19, 1, 0) + (E19 * E66) + (F19 * F66) + (G19 * G66) + (H19 * H66) + (I19 * I66) + (J19 * J66) + (K19 * K66) -> 51 | D19: FALSE | E19: 0 | F19: 4 | G19: 5 | H19: 5 | I19: 4 | J19: 4 | K19: 4
A20: Teste 1 - Cenário Cabine Barba Rosa 2D - 25/12/2025 | B20: =C20/B49 * 100 -> 80.28169 | C20: =IF(D20, 1, 0) + (E20 * E67) + (F20 * F67) + (G20 * G67) + (H20 * H67) + (I20 * I67) + (J20 * J67) + (K20 * K67) -> 57 | D20: FALSE | E20: 0 | F20: 4 | G20: 5 | H20: 5 | I20: 5 | J20: 5 | K20: 4
A21: Teste 2 - Cenário Cabine Barba Rosa 2D Isométrico - 25/12/2025 | B21: =C21/B49 * 100 -> 76.056338 | C21: =IF(D21, 1, 0) + (E21 * E68) + (F21 * F68) + (G21 * G68) + (H21 * H68) + (I21 * I68) + (J21 * J68) + (K21 * K68) -> 54 | D21: FALSE | E21: 0 | F21: 4 | G21: 5 | H21: 5 | I21: 5 | J21: 4 | K21: 4
A22: Teste 3 - Cenário Cabine Barba Rosa 2D de cima - 25/12/2025 | B22: =C22/B49 * 100 -> 80.28169 | C22: =IF(D22, 1, 0) + (E22 * E69) + (F22 * F69) + (G22 * G69) + (H22 * H69) + (I22 * I69) + (J22 * J69) + (K22 * K69) -> 57 | D22: FALSE | E22: 0 | F22: 4 | G22: 5 | H22: 5 | I22: 5 | J22: 5 | K22: 4
A23: Teste 1 - Cenário2 Bar Pirata 2D - 26/12/2025 | B23: =C23/B49 * 100 -> 71.830986 | C23: =IF(D23, 1, 0) + (E23 * E70) + (F23 * F70) + (G23 * G70) + (H23 * H70) + (I23 * I70) + (J23 * J70) + (K23 * K70) -> 51 | D23: FALSE | E23: 0 | F23: 4 | G23: 5 | H23: 5 | I23: 5 | J23: 3 | K23: 4
A24: Teste 2 - Cenário2 Bar Pirata 2D Isométrico - 26/12/2025 | B24: =C24/B49 * 100 -> 71.830986 | C24: =IF(D24, 1, 0) + (E24 * E71) + (F24 * F71) + (G24 * G71) + (H24 * H71) + (I24 * I71) + (J24 * J71) + (K24 * K71) -> 51 | D24: FALSE | E24: 0 | F24: 4 | G24: 5 | H24: 5 | I24: 5 | J24: 3 | K24: 4
A25: Teste 3 - Cenário2 Bar Pirata 2D de cima - 26/12/2025 | B25: =C25/B49 * 100 -> 76.056338 | C25: =IF(D25, 1, 0) + (E25 * E72) + (F25 * F72) + (G25 * G72) + (H25 * H72) + (I25 * I72) + (J25 * J72) + (K25 * K72) -> 54 | D25: FALSE | E25: 0 | F25: 4 | G25: 5 | H25: 5 | I25: 5 | J25: 4 | K25: 4
A26: Teste 1 - Cenário3 Centro da cidade 2D - 26/12/2025 | B26: =C26/B49 * 100 -> 78.873239 | C26: =IF(D26, 1, 0) + (E26 * E73) + (F26 * F73) + (G26 * G73) + (H26 * H73) + (I26 * I73) + (J26 * J73) + (K26 * K73) -> 56 | D26: TRUE | E26: 2 | F26: 4 | G26: 5 | H26: 5 | I26: 5 | J26: 3 | K26: 4
A27: Teste 2 - Cenário3 Centro da cidade Isométrico - 26/12/2025 | B27: =C27/B49 * 100 -> 71.830986 | C27: =IF(D27, 1, 0) + (E27 * E74) + (F27 * F74) + (G27 * G74) + (H27 * H74) + (I27 * I74) + (J27 * J74) + (K27 * K74) -> 51 | D27: TRUE | E27: 1 | F27: 4 | G27: 5 | H27: 5 | I27: 4 | J27: 3 | K27: 4
A28: Teste 3 - Cenário3 Centro da cidade 2D de cima - 26/12/2025 | B28: =C28/B49 * 100 -> 81.690141 | C28: =IF(D28, 1, 0) + (E28 * E75) + (F28 * F75) + (G28 * G75) + (H28 * H75) + (I28 * I75) + (J28 * J75) + (K28 * K75) -> 58 | D28: TRUE | E28: 3 | F28: 4 | G28: 5 | H28: 5 | I28: 4 | J28: 4 | K28: 4
A29: Teste 1 - Textura de madeira - 26/12/2025 | B29: =C29/B49 * 100 -> 67.605634 | C29: =IF(D29, 1, 0) + (E29 * E76) + (F29 * F76) + (G29 * G76) + (H29 * H76) + (I29 * I76) + (J29 * J76) + (K29 * K76) -> 48 | D29: FALSE | E29: 0 | F29: 4 | G29: 5 | H29: 5 | I29: 3 | J29: 4 | K29: 4
A30: Teste 2 - Textura de mar/oceano - 26/12/2025 | B30: =C30/B49 * 100 -> 67.605634 | C30: =IF(D30, 1, 0) + (E30 * E77) + (F30 * F77) + (G30 * G77) + (H30 * H77) + (I30 * I77) + (J30 * J77) + (K30 * K77) -> 48 | D30: FALSE | E30: 0 | F30: 4 | G30: 5 | H30: 5 | I30: 3 | J30: 4 | K30: 4
A31: Teste 2 - Textura de parede com padrao que repete - 26/12/2025 | B31: =C31/B49 * 100 -> 67.605634 | C31: =IF(D31, 1, 0) + (E31 * E78) + (F31 * F78) + (G31 * G78) + (H31 * H78) + (I31 * I78) + (J31 * J78) + (K31 * K78) -> 48 | D31: FALSE | E31: 0 | F31: 4 | G31: 5 | H31: 5 | I31: 3 | J31: 4 | K31: 4
A32: Teste 1 - Arte da capa - 28/12/2025 | B32: =C32/B49 * 100 -> 77.464789 | C32: =IF(D32, 1, 0) + (E32 * E79) + (F32 * F79) + (G32 * G79) + (H32 * H79) + (I32 * I79) + (J32 * J79) + (K32 * K79) -> 55 | D32: TRUE | E32: 3 | F32: 4 | G32: 5 | H32: 5 | I32: 4 | J32: 3 | K32: 4
A33: Teste 2 - Arte da tela de configurações - 28/12/2025 | B33: =C33/B49 * 100 -> 77.464789 | C33: =IF(D33, 1, 0) + (E33 * E80) + (F33 * F80) + (G33 * G80) + (H33 * H80) + (I33 * I80) + (J33 * J80) + (K33 * K80) -> 55 | D33: TRUE | E33: 3 | F33: 4 | G33: 5 | H33: 5 | I33: 4 | J33: 3 | K33: 4
A34: Teste 3 - Arte da tela de ajuda - 28/12/2025 | B34: =C34/B49 * 100 -> 73.239437 | C34: =IF(D34, 1, 0) + (E34 * E81) + (F34 * F81) + (G34 * G81) + (H34 * H81) + (I34 * I81) + (J34 * J81) + (K34 * K81) -> 52 | D34: TRUE | E34: 3 | F34: 4 | G34: 5 | H34: 5 | I34: 3 | J34: 3 | K34: 4
A35: Teste 1 - Botão - 29/12/2025 | B35: =C35/B49 * 100 -> 76.056338 | C35: =IF(D35, 1, 0) + (E35 * E82) + (F35 * F82) + (G35 * G82) + (H35 * H82) + (I35 * I82) + (J35 * J82) + (K35 * K82) -> 54 | D35: FALSE | E35: 0 | F35: 4 | G35: 5 | H35: 5 | I35: 5 | J35: 4 | K35: 4
A36: Teste 2 - Inventário - 29/12/2025 | B36: =C36/B49 * 100 -> 76.056338 | C36: =IF(D36, 1, 0) + (E36 * E83) + (F36 * F83) + (G36 * G83) + (H36 * H83) + (I36 * I83) + (J36 * J83) + (K36 * K83) -> 54 | D36: FALSE | E36: 0 | F36: 4 | G36: 5 | H36: 5 | I36: 5 | J36: 4 | K36: 4
A37: Teste 3 - Cursor - 29/12/2025 | B37: =C37/B49 * 100 -> 67.605634 | C37: =IF(D37, 1, 0) + (E37 * E84) + (F37 * F84) + (G37 * G84) + (H37 * H84) + (I37 * I84) + (J37 * J84) + (K37 * K84) -> 48 | D37: FALSE | E37: 0 | F37: 4 | G37: 5 | H37: 5 | I37: 3 | J37: 4 | K37: 4
A38: Médias | B38: =MEDIAN(Tabela_2[Nota Final (%)]) -> 76.056338 | C38: =MEDIAN(Tabela_2[Pontos Totais (max 71)]) -> 54 | E38: =AVERAGE(Tabela_2[o texo é legivel?]) -> 0.83333333 | F38: =AVERAGE(Tabela_2[Resolução]) -> 4 | G38: =AVERAGE(Tabela_2[Qualidade Visual]) -> 5 | H38: =AVERAGE(Tabela_2[Enquadramento]) -> 5 | I38: =AVERAGE(Tabela_2[Alinhamento Prompt]) -> 4.3611111 | J38: =MEDIAN(Tabela_2[Alucinações]) -> 4 | K38: =AVERAGE(Tabela_2[Tamanho Prompt]) -> 4
J40: 0 é que tem muita alucinação e 5 não tem
A49: Max de pontos | B49: =1 + (5 * E49) + (5 * F49) + (5 * G49) + (5 * H49) + (5 * I49) + (5* J49) + (5* K49) -> 71 | C49: Pesos | D49: 1 | E49: 2 | F49: 1 | G49: 2 | H49: 1 | I49: 3 | J49: 3 | K49: 2
...

Sheet Juggernaut XL
A1: Nome do Teste | B1: Nota Final (%) | C1: Pontos Totais (max 71) | D1: Tem Texto? | E1: o texo é legivel? | F1: Resolução | G1: Qualidade Visual | H1: Enquadramento | I1: Alinhamento Prompt | J1: Alucinações | K1: Tamanho Prompt
A2: Teste 1 - Personagem Pinkbob de frente - 15/12/2025 | B2: =C2/B49 * 100 -> 57.746479 | C2: =IF(D2, 1, 0) + (E2 * E49) + (F2 * F49) + (G2 * G49) + (H2 * H49) + (I2 * I49) + (J3 * J49) + (K2 * K49) -> 41 | D2: FALSE | E2: 0 | F2: 3 | G2: 4 | H2: 5 | I2: 2 | J2: 2 | K2: 5
A3: Teste 2 - Personagem Pinkbob de lado - 15/12/2025 | B3: =C3/B49 * 100 -> 59.15493 | C3: =IF(D3, 1, 0) + (E3 * E50) + (F3 * F50) + (G3 * G50) + (H3 * H50) + (I3 * I50) + (J3 * J50) + (K3 * K50) -> 42 | D3: TRUE | E3: 0 | F3: 3 | G3: 4 | H3: 5 | I3: 2 | J3: 3 | K3: 5
A4: Teste 3 - Personagem Pinkbob de costas - 15/12/2025 | B4: =C4/B49 * 100 -> 53.521127 | C4: =IF(D4, 1, 0) + (E4 * E51) + (F4 * F51) + (G4 * G51) + (H4 * H51) + (I4 * I51) + (J4 * J51) + (K4 * K51) -> 38 | D4: FALSE | E4: 0 | F4: 3 | G4: 4 | H4: 5 | I4: 2 | J4: 2 | K4: 5
A5: Teste 1 - Personagem2 Barba Rosa de frente - 15/12/2025 | B5: =C5/B49 * 100 -> 53.521127 | C5: =IF(D5, 1, 0) + (E5 * E52) + (F5 * F52) + (G5 * G52) + (H5 * H52) + (I5 * I52) + (J5 * J52) + (K5 * K52) -> 38 | D5: FALSE | E5: 0 | F5: 3 | G5: 4 | H5: 5 | I5: 2 | J5: 2 | K5: 5
A6: Teste 2 - Personagem2 Barba Rosa de lado - 15/12/2025 | B6: =C6/B49 * 100 -> 57.746479 | C6: =IF(D6, 1, 0) + (E6 * E53) + (F6 * F53) + (G6 * G53) + (H6 * H53) + (I6 * I53) + (J6 * J53) + (K6 * K53) -> 41 | D6: FALSE | E6: 0 | F6: 3 | G6: 4 | H6: 5 | I6: 2 | J6: 3 | K6: 5
A7: Teste 3 - Personagem2 Barba Rosa de costas - 15/12/2025 | B7: =C7/B49 * 100 -> 53.521127 | C7: =IF(D7, 1, 0) + (E7 * E54) + (F7 * F54) + (G7 * G54) + (H7 * H54) + (I7 * I54) + (J7 * J54) + (K7 * K54) -> 38 | D7: FALSE | E7: 0 | F7: 3 | G7: 4 | H7: 5 | I7: 2 | J7: 2 | K7: 5
A8: Teste 1 - Personagem3 João de frente - 16/12/2025 | B8: =C8/B49 * 100 -> 53.521127 | C8: =IF(D8, 1, 0) + (E8 * E55) + (F8 * F55) + (G8 * G55) + (H8 * H55) + (I8 * I55) + (J8 * J55) + (K8 * K55) -> 38 | D8: FALSE | E8: 0 | F8: 3 | G8: 4 | H8: 5 | I8: 3 | J8: 1 | K8: 5
A9: Teste 2 - Personagem3 João de lado - 16/12/2025 | B9: =C9/B49 * 100 -> 49.295775 | C9: =IF(D9, 1, 0) + (E9 * E56) + (F9 * F56) + (G9 * G56) + (H9 * H56) + (I9 * I56) + (J9 * J56) + (K9 * K56) -> 35 | D9: FALSE | E9: 0 | F9: 3 | G9: 4 | H9: 5 | I9: 2 | J9: 1 | K9: 5
A10: Teste 3 - Personagem3 João de costas - 16/12/2025 | B10: =C10/B49 * 100 -> 53.521127 | C10: =IF(D10, 1, 0) + (E10 * E57) + (F10 * F57) + (G10 * G57) + (H10 * H57) + (I10 * I57) + (J10 * J57) + (K10 * K57) -> 38 | D10: FALSE | E10: 0 | F10: 3 | G10: 4 | H10: 5 | I10: 2 | J10: 2 | K10: 5
A11: Teste 1 - Objeto bussola de frente - 18/12/2025 | B11: =C11/B49 * 100 -> 70.422535 | C11: =IF(D11, 1, 0) + (E11 * E58) + (F11 * F58) + (G11 * G58) + (H11 * H58) + (I11 * I58) + (J11 * J58) + (K11 * K58) -> 50 | D11: FALSE | E11: 0 | F11: 3 | G11: 4 | H11: 5 | I11: 4 | J11: 4 | K11: 5
A12: Teste 2 - Objeto bussola de lado - 18/12/2025 | B12: =C12/B49 * 100 -> 61.971831 | C12: =IF(D12, 1, 0) + (E12 * E59) + (F12 * F59) + (G12 * G59) + (H12 * H59) + (I12 * I59) + (J12 * J59) + (K12 * K59) -> 44 | D12: FALSE | E12: 0 | F12: 3 | G12: 4 | H12: 5 | I12: 3 | J12: 3 | K12: 5
A13: Teste 3 - Objeto bussola de costas - 18/12/2025 | B13: =C13/B49 * 100 -> 53.521127 | C13: =IF(D13, 1, 0) + (E13 * E60) + (F13 * F60) + (G13 * G60) + (H13 * H60) + (I13 * I60) + (J13 * J60) + (K13 * K60) -> 38 | D13: FALSE | E13: 0 | F13: 3 | G13: 4 | H13: 5 | I13: 2 | J13: 2 | K13: 5
A14: Teste 1 - Objeto2 mesa de frente - 18/12/2025 | B14: =C14/B49 * 100 -> 60.56338 | C14: =IF(D14, 1, 0) + (E14 * E61) + (F14 * F61) + (G14 * G61) + (H14 * H61) + (I14 * I61) + (J14 * J61) + (K14 * K61) -> 43 | D14: FALSE | E14: 0 | F14: 3 | G14: 5 | H14: 5 | I14: 3 | J14: 2 | K14: 5
A15: Teste 2 - Objeto2 mesa de lado - 18/12/2025 | B15: =C15/B49 * 100 -> 53.521127 | C15: =IF(D15, 1, 0) + (E15 * E62) + (F15 * F62) + (G15 * G62) + (H15 * H62) + (I15 * I62) + (J15 * J62) + (K15 * K62) -> 38 | D15: FALSE | E15: 0 | F15: 3 | G15: 4 | H15: 5 | I15: 2 | J15: 2 | K15: 5
A16: Teste 3 - Objeto2 mesa de costas - 18/12/2025 | B16: =C16/B49 * 100 -> 56.338028 | C16: =IF(D16, 1, 0) + (E16 * E63) + (F16 * F63) + (G16 * G63) + (H16 * H63) + (I16 * I63) + (J16 * J63) + (K16 * K63) -> 40 | D16: FALSE | E16: 0 | F16: 3 | G16: 5 | H16: 5 | I16: 2 | J16: 2 | K16: 5
A17: Teste 1 - Objeto3 espada pirata de frente - 23/12/2025 | B17: =C17/B49 * 100 -> 53.521127 | C17: =IF(D17, 1, 0) + (E17 * E64) + (F17 * F64) + (G17 * G64) + (H17 * H64) + (I17 * I64) + (J17 * J64) + (K17 * K64) -> 38 | D17: FALSE | E17: 0 | F17: 3 | G17: 4 | H17: 5 | I17: 3 | J17: 1 | K17: 5
A18: Teste 2 - Objeto3 espada pirata de lado - 23/12/2025 | B18: =C18/B49 * 100 -> 69.014085 | C18: =IF(D18, 1, 0) + (E18 * E65) + (F18 * F65) + (G18 * G65) + (H18 * H65) + (I18 * I65) + (J18 * J65) + (K18 * K65) -> 49 | D18: FALSE | E18: 0 | F18: 3 | G18: 5 | H18: 5 | I18: 3 | J18: 4 | K18: 5
A19: Teste 3 - Objeto3 espada pirata de costas - 23/12/2025 | B19: =C19/B49 * 100 -> 69.014085 | C19: =IF(D19, 1, 0) + (E19 * E66) + (F19 * F66) + (G19 * G66) + (H19 * H66) + (I19 * I66) + (J19 * J66) + (K19 * K66) -> 49 | D19: FALSE | E19: 0 | F19: 3 | G19: 5 | H19: 5 | I19: 3 | J19: 4 | K19: 5
A20: Teste 1 - Cenário Cabine Barba Rosa 2D - 25/12/2025 | B20: =C20/B49 * 100 -> 50.704225 | C20: =IF(D20, 1, 0) + (E20 * E67) + (F20 * F67) + (G20 * G67) + (H20 * H67) + (I20 * I67) + (J20 * J67) + (K20 * K67) -> 36 | D20: FALSE | E20: 0 | F20: 3 | G20: 3 | H20: 5 | I20: 2 | J20: 2 | K20: 5
A21: Teste 2 - Cenário Cabine Barba Rosa 2D Isométrico - 25/12/2025 | B21: =C21/B49 * 100 -> 46.478873 | C21: =IF(D21, 1, 0) + (E21 * E68) + (F21 * F68) + (G21 * G68) + (H21 * H68) + (I21 * I68) + (J21 * J68) + (K21 * K68) -> 33 | D21: FALSE | E21: 0 | F21: 3 | G21: 3 | H21: 5 | I21: 1 | J21: 2 | K21: 5
A22: Teste 3 - Cenário Cabine Barba Rosa 2D de cima - 25/12/2025 | B22: =C22/B49 * 100 -> 46.478873 | C22: =IF(D22, 1, 0) + (E22 * E69) + (F22 * F69) + (G22 * G69) + (H22 * H69) + (I22 * I69) + (J22 * J69) + (K22 * K69) -> 33 | D22: FALSE | E22: 0 | F22: 3 | G22: 3 | H22: 5 | I22: 1 | J22: 2 | K22: 5
A23: Teste 1 - Cenário2 Bar Pirata 2D - 26/12/2025 | B23: =C23/B49 * 100 -> 50.704225 | C23: =IF(D23, 1, 0) + (E23 * E70) + (F23 * F70) + (G23 * G70) + (H23 * H70) + (I23 * I70) + (J23 * J70) + (K23 * K70) -> 36 | D23: FALSE | E23: 0 | F23: 3 | G23: 3 | H23: 5 | I23: 2 | J23: 2 | K23: 5
A24: Teste 2 - Cenário2 Bar Pirata 2D Isométrico - 26/12/2025 | B24: =C24/B49 * 100 -> 54.929577 | C24: =IF(D24, 1, 0) + (E24 * E71) + (F24 * F71) + (G24 * G71) + (H24 * H71) + (I24 * I71) + (J24 * J71) + (K24 * K71) -> 39 | D24: FALSE | E24: 0 | F24: 3 | G24: 3 | H24: 5 | I24: 3 | J24: 2 | K24: 5
A25: Teste 3 - Cenário2 Bar Pirata 2D de cima - 26/12/2025 | B25: =C25/B49 * 100 -> 49.295775 | C25: =IF(D25, 1, 0) + (E25 * E72) + (F25 * F72) + (G25 * G72) + (H25 * H72) + (I25 * I72) + (J25 * J72) + (K25 * K72) -> 35 | D25: FALSE | E25: 0 | F25: 3 | G25: 4 | H25: 5 | I25: 1 | J25: 2 | K25: 5
A26: Teste 1 - Cenário3 Centro da cidade 2D - 26/12/2025 | B26: =C26/B49 * 100 -> 66.197183 | C26: =IF(D26, 1, 0) + (E26 * E73) + (F26 * F73) + (G26 * G73) + (H26 * H73) + (I26 * I73) + (J26 * J73) + (K26 * K73) -> 47 | D26: TRUE | E26: 1 | F26: 3 | G26: 4 | H26: 5 | I26: 3 | J26: 3 | K26: 5
A27: Teste 2 - Cenário3 Centro da cidade Isométrico - 26/12/2025 | B27: =C27/B49 * 100 -> 66.197183 | C27: =IF(D27, 1, 0) + (E27 * E74) + (F27 * F74) + (G27 * G74) + (H27 * H74) + (I27 * I74) + (J27 * J74) + (K27 * K74) -> 47 | D27: TRUE | E27: 1 | F27: 3 | G27: 4 | H27: 5 | I27: 3 | J27: 3 | K27: 5
A28: Teste 3 - Cenário3 Centro da cidade 2D de cima - 26/12/2025 | B28: =C28/B49 * 100 -> 57.746479 | C28: =IF(D28, 1, 0) + (E28 * E75) + (F28 * F75) + (G28 * G75) + (H28 * H75) + (I28 * I75) + (J28 * J75) + (K28 * K75) -> 41 | D28: FALSE | E28: 0 | F28: 3 | G28: 4 | H28: 5 | I28: 2 | J28: 3 | K28: 5
A29: Teste 1 - Textura de madeira - 26/12/2025 | B29: =C29/B49 * 100 -> 77.464789 | C29: =IF(D29, 1, 0) + (E29 * E76) + (F29 * F76) + (G29 * G76) + (H29 * H76) + (I29 * I76) + (J29 * J76) + (K29 * K76) -> 55 | D29: FALSE | E29: 0 | F29: 3 | G29: 5 | H29: 5 | I29: 4 | J29: 5 | K29: 5
A30: Teste 2 - Textura de mar/oceano - 26/12/2025 | B30: =C30/B49 * 100 -> 73.239437 | C30: =IF(D30, 1, 0) + (E30 * E77) + (F30 * F77) + (G30 * G77) + (H30 * H77) + (I30 * I77) + (J30 * J77) + (K30 * K77) -> 52 | D30: FALSE | E30: 0 | F30: 3 | G30: 5 | H30: 5 | I30: 4 | J30: 4 | K30: 5
A31: Teste 2 - Textura de parede com padrao que repete - 26/12/2025 | B31: =C31/B49 * 100 -> 69.014085 | C31: =IF(D31, 1, 0) + (E31 * E78) + (F31 * F78) + (G31 * G78) + (H31 * H78) + (I31 * I78) + (J31 * J78) + (K31 * K78) -> 49 | D31: FALSE | E31: 0 | F31: 3 | G31: 5 | H31: 5 | I31: 3 | J31: 4 | K31: 5
A32: Teste 1 - Arte da capa - 28/12/2025 | B32: =C32/B49 * 100 -> 50.704225 | C32: =IF(D32, 1, 0) + (E32 * E79) + (F32 * F79) + (G32 * G79) + (H32 * H79) + (I32 * I79) + (J32 * J79) + (K32 * K79) -> 36 | D32: FALSE | E32: 0 | F32: 3 | G32: 3 | H32: 5 | I32: 3 | J32: 1 | K32: 5
A33: Teste 2 - Arte da tela de configurações - 28/12/2025 | B33: =C33/B49 * 100 -> 54.929577 | C33: =IF(D33, 1, 0) + (E33 * E80) + (F33 * F80) + (G33 * G80) + (H33 * H80) + (I33 * I80) + (J33 * J80) + (K33 * K80) -> 39 | D33: TRUE | E33: 1 | F33: 3 | G33: 3 | H33: 5 | I33: 3 | J33: 1 | K33: 5
A34: Teste 3 - Arte da tela de ajuda - 28/12/2025 | B34: =C34/B49 * 100 -> 59.15493 | C34: =IF(D34, 1, 0) + (E34 * E81) + (F34 * F81) + (G34 * G81) + (H34 * H81) + (I34 * I81) + (J34 * J81) + (K34 * K81) -> 42 | D34: TRUE | E34: 1 | F34: 3 | G34: 3 | H34: 5 | I34: 3 | J34: 2 | K34: 5
A35: Teste 1 - Botão - 29/12/2025 | B35: =C35/B49 * 100 -> 50.704225 | C35: =IF(D35, 1, 0) + (E35 * E82) + (F35 * F82) + (G35 * G82) + (H35 * H82) + (I35 * I82) + (J35 * J82) + (K35 * K82) -> 36 | D35: FALSE | E35: 0 | F35: 3 | G35: 3 | H35: 5 | I35: 2 | J35: 2 | K35: 5
A36: Teste 2 - Inventário - 29/12/2025 | B36: =C36/B49 * 100 -> 42.253521 | C36: =IF(D36, 1, 0) + (E36 * E83) + (F36 * F83) + (G36 * G83) + (H36 * H83) + (I36 * I83) + (J36 * J83) + (K36 * K83) -> 30 | D36: FALSE | E36: 0 | F36: 3 | G36: 3 | H36: 5 | I36: 1 | J36: 1 | K36: 5
A37: Teste 3 - Cursor - 29/12/2025 | B37: =C37/B49 * 100 -> 50.704225 | C37: =IF(D37, 1, 0) + (E37 * E84) + (F37 * F84) + (G37 * G84) + (H37 * H84) + (I37 * I84) + (J37 * J84) + (K37 * K84) -> 36 | D37: FALSE | E37: 0 | F37: 3 | G37: 3 | H37: 5 | I37: 3 | J37: 1 | K37: 5
A38: Médias | B38: =MEDIAN(Tabela_3[Nota Final (%)]) -> 54.225352 | C38: =MEDIAN(Tabela_3[Pontos Totais (max 71)]) -> 38.5 | E38: =AVERAGE(Tabela_3[o texo é legivel?]) -> 0.11111111 | F38: =AVERAGE(Tabela_3[Resolução]) -> 3 | G38: =AVERAGE(Tabela_3[Qualidade Visual]) -> 3.8888889 | H38: =AVERAGE(Tabela_3[Enquadramento]) -> 5 | I38: =AVERAGE(Tabela_3[Alinhamento Prompt]) -> 2.4444444 | J38: =MEDIAN(Tabela_3[Alucinações]) -> 2 | K38: =AVERAGE(Tabela_3[Tamanho Prompt]) -> 5
J40: 0 é que tem muita alucinação e 5 não tem
A49: Max de pontos | B49: =1 + (5 * E49) + (5 * F49) + (5 * G49) + (5 * H49) + (5 * I49) + (5* J49) + (5* K49) -> 71 | C49: Pesos | D49: 1 | E49: 2 | F49: 1 | G49: 2 | H49: 1 | I49: 3 | J49: 3 | K49: 2
...

Sheet CHEYENNE
A1: Nome do Teste | B1: Nota Final (%) | C1: Pontos Totais (max 71) | D1: Tem Texto? | E1: o texo é legivel? | F1: Resolução | G1: Qualidade Visual | H1: Enquadramento | I1: Alinhamento Prompt | J1: Alucinações | K1: Tamanho Prompt
A2: Teste 1 - Personagem Pinkbob de frente - 15/12/2025 | B2: =C2/B49 * 100 -> 53.521127 | C2: =IF(D2, 1, 0) + (E2 * E49) + (F2 * F49) + (G2 * G49) + (H2 * H49) + (I2 * I49) + (J3 * J49) + (K2 * K49) -> 38 | D2: FALSE | E2: 0 | F2: 3 | G2: 4 | H2: 5 | I2: 2 | J2: 2 | K2: 5
A3: Teste 2 - Personagem Pinkbob de lado - 15/12/2025 | B3: =C3/B49 * 100 -> 50.704225 | C3: =IF(D3, 1, 0) + (E3 * E50) + (F3 * F50) + (G3 * G50) + (H3 * H50) + (I3 * I50) + (J3 * J50) + (K3 * K50) -> 36 | D3: FALSE | E3: 0 | F3: 3 | G3: 4 | H3: 3 | I3: 2 | J3: 2 | K3: 5
A4: Teste 3 - Personagem Pinkbob de costas - 15/12/2025 | B4: =C4/B49 * 100 -> 50.704225 | C4: =IF(D4, 1, 0) + (E4 * E51) + (F4 * F51) + (G4 * G51) + (H4 * H51) + (I4 * I51) + (J4 * J51) + (K4 * K51) -> 36 | D4: FALSE | E4: 0 | F4: 3 | G4: 4 | H4: 3 | I4: 2 | J4: 2 | K4: 5
A5: Teste 1 - Personagem2 Barba Rosa de frente - 15/12/2025 | B5: =C5/B49 * 100 -> 59.15493 | C5: =IF(D5, 1, 0) + (E5 * E52) + (F5 * F52) + (G5 * G52) + (H5 * H52) + (I5 * I52) + (J5 * J52) + (K5 * K52) -> 42 | D5: FALSE | E5: 0 | F5: 3 | G5: 4 | H5: 3 | I5: 3 | J5: 3 | K5: 5
A6: Teste 2 - Personagem2 Barba Rosa de lado - 15/12/2025 | B6: =C6/B49 * 100 -> 52.112676 | C6: =IF(D6, 1, 0) + (E6 * E53) + (F6 * F53) + (G6 * G53) + (H6 * H53) + (I6 * I53) + (J6 * J53) + (K6 * K53) -> 37 | D6: FALSE | E6: 0 | F6: 3 | G6: 4 | H6: 1 | I6: 2 | J6: 3 | K6: 5
A7: Teste 3 - Personagem2 Barba Rosa de costas - 15/12/2025 | B7: =C7/B49 * 100 -> 46.478873 | C7: =IF(D7, 1, 0) + (E7 * E54) + (F7 * F54) + (G7 * G54) + (H7 * H54) + (I7 * I54) + (J7 * J54) + (K7 * K54) -> 33 | D7: FALSE | E7: 0 | F7: 3 | G7: 4 | H7: 3 | I7: 1 | J7: 2 | K7: 5
A8: Teste 1 - Personagem3 João de frente - 16/12/2025 | B8: =C8/B49 * 100 -> 56.338028 | C8: =IF(D8, 1, 0) + (E8 * E55) + (F8 * F55) + (G8 * G55) + (H8 * H55) + (I8 * I55) + (J8 * J55) + (K8 * K55) -> 40 | D8: FALSE | E8: 0 | F8: 3 | G8: 4 | H8: 4 | I8: 3 | J8: 2 | K8: 5
A9: Teste 2 - Personagem3 João de lado - 16/12/2025 | B9: =C9/B49 * 100 -> 49.295775 | C9: =IF(D9, 1, 0) + (E9 * E56) + (F9 * F56) + (G9 * G56) + (H9 * H56) + (I9 * I56) + (J9 * J56) + (K9 * K56) -> 35 | D9: FALSE | E9: 0 | F9: 3 | G9: 4 | H9: 5 | I9: 1 | J9: 2 | K9: 5
A10: Teste 3 - Personagem3 João de costas - 16/12/2025 | B10: =C10/B49 * 100 -> 57.746479 | C10: =IF(D10, 1, 0) + (E10 * E57) + (F10 * F57) + (G10 * G57) + (H10 * H57) + (I10 * I57) + (J10 * J57) + (K10 * K57) -> 41 | D10: FALSE | E10: 0 | F10: 3 | G10: 4 | H10: 5 | I10: 3 | J10: 2 | K10: 5
A11: Teste 1 - Objeto bussola de frente - 18/12/2025 | B11: =C11/B49 * 100 -> 46.478873 | C11: =IF(D11, 1, 0) + (E11 * E58) + (F11 * F58) + (G11 * G58) + (H11 * H58) + (I11 * I58) + (J11 * J58) + (K11 * K58) -> 33 | D11: FALSE | E11: 0 | F11: 3 | G11: 3 | H11: 5 | I11: 2 | J11: 1 | K11: 5
A12: Teste 2 - Objeto bussola de lado - 18/12/2025 | B12: =C12/B49 * 100 -> 54.929577 | C12: =IF(D12, 1, 0) + (E12 * E59) + (F12 * F59) + (G12 * G59) + (H12 * H59) + (I12 * I59) + (J12 * J59) + (K12 * K59) -> 39 | D12: FALSE | E12: 0 | F12: 3 | G12: 3 | H12: 5 | I12: 2 | J12: 3 | K12: 5
A13: Teste 3 - Objeto bussola de costas - 18/12/2025 | B13: =C13/B49 * 100 -> 42.253521 | C13: =IF(D13, 1, 0) + (E13 * E60) + (F13 * F60) + (G13 * G60) + (H13 * H60) + (I13 * I60) + (J13 * J60) + (K13 * K60) -> 30 | D13: FALSE | E13: 0 | F13: 3 | G13: 3 | H13: 5 | I13: 1 | J13: 1 | K13: 5
A14: Teste 1 - Objeto2 mesa de frente - 18/12/2025 | B14: =C14/B49 * 100 -> 42.253521 | C14: =IF(D14, 1, 0) + (E14 * E61) + (F14 * F61) + (G14 * G61) + (H14 * H61) + (I14 * I61) + (J14 * J61) + (K14 * K61) -> 30 | D14: FALSE | E14: 0 | F14: 3 | G14: 3 | H14: 2 | I14: 2 | J14: 1 | K14: 5
A15: Teste 2 - Objeto2 mesa de lado - 18/12/2025 | B15: =C15/B49 * 100 -> 42.253521 | C15: =IF(D15, 1, 0) + (E15 * E62) + (F15 * F62) + (G15 * G62) + (H15 * H62) + (I15 * I62) + (J15 * J62) + (K15 * K62) -> 30 | D15: FALSE | E15: 0 | F15: 3 | G15: 3 | H15: 2 | I15: 2 | J15: 1 | K15: 5
A16: Teste 3 - Objeto2 mesa de costas - 18/12/2025 | B16: =C16/B49 * 100 -> 40.84507 | C16: =IF(D16, 1, 0) + (E16 * E63) + (F16 * F63) + (G16 * G63) + (H16 * H63) + (I16 * I63) + (J16 * J63) + (K16 * K63) -> 29 | D16: FALSE | E16: 0 | F16: 3 | G16: 3 | H16: 4 | I16: 1 | J16: 1 | K16: 5
A17: Teste 1 - Objeto3 espada pirata de frente - 23/12/2025 | B17: =C17/B49 * 100 -> 67.605634 | C17: =IF(D17, 1, 0) + (E17 * E64) + (F17 * F64) + (G17 * G64) + (H17 * H64) + (I17 * I64) + (J17 * J64) + (K17 * K64) -> 48 | D17: FALSE | E17: 0 | F17: 3 | G17: 3 | H17: 5 | I17: 4 | J17: 4 | K17: 5
A18: Teste 2 - Objeto3 espada pirata de lado - 23/12/2025 | B18: =C18/B49 * 100 -> 59.15493 | C18: =IF(D18, 1, 0) + (E18 * E65) + (F18 * F65) + (G18 * G65) + (H18 * H65) + (I18 * I65) + (J18 * J65) + (K18 * K65) -> 42 | D18: FALSE | E18: 0 | F18: 3 | G18: 3 | H18: 5 | I18: 3 | J18: 3 | K18: 5
A19: Teste 3 - Objeto3 espada pirata de costas - 23/12/2025 | B19: =C19/B49 * 100 -> 46.478873 | C19: =IF(D19, 1, 0) + (E19 * E66) + (F19 * F66) + (G19 * G66) + (H19 * H66) + (I19 * I66) + (J19 * J66) + (K19 * K66) -> 33 | D19: FALSE | E19: 0 | F19: 3 | G19: 3 | H19: 5 | I19: 1 | J19: 2 | K19: 5
A20: Teste 1 - Cenário Cabine Barba Rosa 2D - 25/12/2025 | B20: =C20/B49 * 100 -> 43.661972 | C20: =IF(D20, 1, 0) + (E20 * E67) + (F20 * F67) + (G20 * G67) + (H20 * H67) + (I20 * I67) + (J20 * J67) + (K20 * K67) -> 31 | D20: FALSE | E20: 0 | F20: 3 | G20: 3 | H20: 3 | I20: 1 | J20: 2 | K20: 5
A21: Teste 2 - Cenário Cabine Barba Rosa 2D Isométrico - 25/12/2025 | B21: =C21/B49 * 100 -> 40.84507 | C21: =IF(D21, 1, 0) + (E21 * E68) + (F21 * F68) + (G21 * G68) + (H21 * H68) + (I21 * I68) + (J21 * J68) + (K21 * K68) -> 29 | D21: FALSE | E21: 0 | F21: 3 | G21: 2 | H21: 3 | I21: 1 | J21: 2 | K21: 5
A22: Teste 3 - Cenário Cabine Barba Rosa 2D de cima - 25/12/2025 | B22: =C22/B49 * 100 -> 43.661972 | C22: =IF(D22, 1, 0) + (E22 * E69) + (F22 * F69) + (G22 * G69) + (H22 * H69) + (I22 * I69) + (J22 * J69) + (K22 * K69) -> 31 | D22: FALSE | E22: 0 | F22: 3 | G22: 3 | H22: 3 | I22: 2 | J22: 1 | K22: 5
A23: Teste 1 - Cenário2 Bar Pirata 2D - 26/12/2025 | B23: =C23/B49 * 100 -> 49.295775 | C23: =IF(D23, 1, 0) + (E23 * E70) + (F23 * F70) + (G23 * G70) + (H23 * H70) + (I23 * I70) + (J23 * J70) + (K23 * K70) -> 35 | D23: FALSE | E23: 0 | F23: 3 | G23: 3 | H23: 4 | I23: 2 | J23: 2 | K23: 5
A24: Teste 2 - Cenário2 Bar Pirata 2D Isométrico - 26/12/2025 | B24: =C24/B49 * 100 -> 47.887324 | C24: =IF(D24, 1, 0) + (E24 * E71) + (F24 * F71) + (G24 * G71) + (H24 * H71) + (I24 * I71) + (J24 * J71) + (K24 * K71) -> 34 | D24: FALSE | E24: 0 | F24: 3 | G24: 3 | H24: 3 | I24: 2 | J24: 2 | K24: 5
A25: Teste 3 - Cenário2 Bar Pirata 2D de cima - 26/12/2025 | B25: =C25/B49 * 100 -> 38.028169 | C25: =IF(D25, 1, 0) + (E25 * E72) + (F25 * F72) + (G25 * G72) + (H25 * H72) + (I25 * I72) + (J25 * J72) + (K25 * K72) -> 27 | D25: FALSE | E25: 0 | F25: 3 | G25: 3 | H25: 2 | I25: 1 | J25: 1 | K25: 5
A26: Teste 1 - Cenário3 Centro da cidade 2D - 26/12/2025 | B26: =C26/B49 * 100 -> 43.661972 | C26: =IF(D26, 1, 0) + (E26 * E73) + (F26 * F73) + (G26 * G73) + (H26 * H73) + (I26 * I73) + (J26 * J73) + (K26 * K73) -> 31 | D26: FALSE | E26: 0 | F26: 3 | G26: 3 | H26: 3 | I26: 2 | J26: 1 | K26: 5
A27: Teste 2 - Cenário3 Centro da cidade Isométrico - 26/12/2025 | B27: =C27/B49 * 100 -> 47.887324 | C27: =IF(D27, 1, 0) + (E27 * E74) + (F27 * F74) + (G27 * G74) + (H27 * H74) + (I27 * I74) + (J27 * J74) + (K27 * K74) -> 34 | D27: FALSE | E27: 0 | F27: 3 | G27: 3 | H27: 3 | I27: 2 | J27: 2 | K27: 5
A28: Teste 3 - Cenário3 Centro da cidade 2D de cima - 26/12/2025 | B28: =C28/B49 * 100 -> 38.028169 | C28: =IF(D28, 1, 0) + (E28 * E75) + (F28 * F75) + (G28 * G75) + (H28 * H75) + (I28 * I75) + (J28 * J75) + (K28 * K75) -> 27 | D28: FALSE | E28: 0 | F28: 3 | G28: 3 | H28: 2 | I28: 1 | J28: 1 | K28: 5
A29: Teste 1 - Textura de madeira - 26/12/2025 | B29: =C29/B49 * 100 -> 61.971831 | C29: =IF(D29, 1, 0) + (E29 * E76) + (F29 * F76) + (G29 * G76) + (H29 * H76) + (I29 * I76) + (J29 * J76) + (K29 * K76) -> 44 | D29: FALSE | E29: 0 | F29: 3 | G29: 4 | H29: 5 | I29: 3 | J29: 3 | K29: 5
A30: Teste 2 - Textura de mar/oceano - 26/12/2025 | B30: =C30/B49 * 100 -> 39.43662 | C30: =IF(D30, 1, 0) + (E30 * E77) + (F30 * F77) + (G30 * G77) + (H30 * H77) + (I30 * I77) + (J30 * J77) + (K30 * K77) -> 28 | D30: FALSE | E30: 0 | F30: 3 | G30: 4 | H30: 1 | I30: 1 | J30: 1 | K30: 5
A31: Teste 2 - Textura de parede com padrao que repete - 26/12/2025 | B31: =C31/B49 * 100 -> 39.43662 | C31: =IF(D31, 1, 0) + (E31 * E78) + (F31 * F78) + (G31 * G78) + (H31 * H78) + (I31 * I78) + (J31 * J78) + (K31 * K78) -> 28 | D31: FALSE | E31: 0 | F31: 3 | G31: 2 | H31: 5 | I31: 1 | J31: 1 | K31: 5
A32: Teste 1 - Arte da capa - 28/12/2025 | B32: =C32/B49 * 100 -> 43.661972 | C32: =IF(D32, 1, 0) + (E32 * E79) + (F32 * F79) + (G32 * G79) + (H32 * H79) + (I32 * I79) + (J32 * J79) + (K32 * K79) -> 31 | D32: FALSE | E32: 0 | F32: 3 | G32: 2 | H32: 5 | I32: 2 | J32: 1 | K32: 5
A33: Teste 2 - Arte da tela de configurações - 28/12/2025 | B33: =C33/B49 * 100 -> 69.014085 | C33: =IF(D33, 1, 0) + (E33 * E80) + (F33 * F80) + (G33 * G80) + (H33 * H80) + (I33 * I80) + (J33 * J80) + (K33 * K80) -> 49 | D33: FALSE | E33: 0 | F33: 3 | G33: 5 | H33: 5 | I33: 3 | J33: 4 | K33: 5
A34: Teste 3 - Arte da tela de ajuda - 28/12/2025 | B34: =C34/B49 * 100 -> 53.521127 | C34: =IF(D34, 1, 0) + (E34 * E81) + (F34 * F81) + (G34 * G81) + (H34 * H81) + (I34 * I81) + (J34 * J81) + (K34 * K81) -> 38 | D34: FALSE | E34: 0 | F34: 3 | G34: 4 | H34: 5 | I34: 2 | J34: 2 | K34: 5
A35: Teste 1 - Botão - 29/12/2025 | B35: =C35/B49 * 100 -> 57.746479 | C35: =IF(D35, 1, 0) + (E35 * E82) + (F35 * F82) + (G35 * G82) + (H35 * H82) + (I35 * I82) + (J35 * J82) + (K35 * K82) -> 41 | D35: FALSE | E35: 0 | F35: 3 | G35: 4 | H35: 5 | I35: 2 | J35: 3 | K35: 5
A36: Teste 2 - Inventário - 29/12/2025 | B36: =C36/B49 * 100 -> 42.253521 | C36: =IF(D36, 1, 0) + (E36 * E83) + (F36 * F83) + (G36 * G83) + (H36 * H83) + (I36 * I83) + (J36 * J83) + (K36 * K83) -> 30 | D36: FALSE | E36: 0 | F36: 3 | G36: 3 | H36: 5 | I36: 1 | J36: 1 | K36: 5
A37: Teste 3 - Cursor - 29/12/2025 | B37: =C37/B49 * 100 -> 57.746479 | C37: =IF(D37, 1, 0) + (E37 * E84) + (F37 * F84) + (G37 * G84) + (H37 * H84) + (I37 * I84) + (J37 * J84) + (K37 * K84) -> 41 | D37: FALSE | E37: 0 | F37: 3 | G37: 4 | H37: 5 | I37: 3 | J37: 2 | K37: 5
A38: Médias | B38: =MEDIAN(Tabela_4[Nota Final (%)]) -> 47.887324 | C38: =MEDIAN(Tabela_4[Pontos Totais (max 71)]) -> 34 | E38: =AVERAGE(Tabela_4[o texo é legivel?]) -> 0 | F38: =AVERAGE(Tabela_4[Resolução]) -> 3 | G38: =AVERAGE(Tabela_4[Qualidade Visual]) -> 3.3611111 | H38: =AVERAGE(Tabela_4[Enquadramento]) -> 3.8055556 | I38: =AVERAGE(Tabela_4[Alinhamento Prompt]) -> 1.9166667 | J38: =MEDIAN(Tabela_4[Alucinações]) -> 2 | K38: =AVERAGE(Tabela_4[Tamanho Prompt]) -> 5
J40: 0 é que tem muita alucinação e 5 não tem
A49: Max de pontos | B49: =1 + (5 * E49) + (5 * F49) + (5 * G49) + (5 * H49) + (5 * I49) + (5* J49) + (5* K49) -> 71 | C49: Pesos | D49: 1 | E49: 2 | F49: 1 | G49: 2 | H49: 1 | I49: 3 | J49: 3 | K49: 2
...

Sheet NetaYume Lumina - ComfyUI
